Workbook

Sheet 주요테마
A1: ■ 주요테마
B2: 테마코드 | C2: 테마분류 | D2: 테마명칭
B3: themeCode | C3: themeClass | D3: themeLabel
B4: battery | C4: t-battery | D4: 2차전지
B5: semi | C5: t-semi | D5: 반도체
B6: bio | C6: t-bio | D6: 바이오
B7: ai | C7: t-ai | D7: AI
B8: green | C8: t-green | D8: 친환경

Sheet 인포스탁
A1: ■ 인포스탁 테마종목
B2: 카테고리 | C2: 섹터 | D2: 테마분류 | E2: 테마명칭 | F2: 테마섹터 | H2: 인포스탁테마 | J2: 테마종목 | K2: 관련이슈
B3: Category | C3: Sector | D3: themeClass | E3: themeLabel | F3: sector-name | G3: sector-en | H3: theme-name | I3: theme-en | J3: stock | K3: remarks
C5: =F5 -> 산업 | F5: 산업 | G5: Industry
C6: =G6 | E6: =H6 -> 건설중소형 | H6: 건설중소형 | I6: construct_industry | J6: KCC건설, 동부건설, 대원, 남화토건, 신원종합개발
C7: =G7 | E7: =H7 -> 건설기계 | H7: 건설기계 | I7: construct_equip | J7: 두산밥캣, HD현대건설기계, 전진건설로봇, 진성티이씨, 대창단조, 서연탑메탈
C8: =G8 | E8: =H8 -> 게임 | H8: 게임 | I8: game | J8: 엔씨소프트, 크래프톤, 넷마블,펄어비스, 위메이드
E9: =H9 -> 로봇 | H9: 로봇 | I9: robot | J9: 레인보우로보틱스, 로보티즈, 로보로보, 클로봇, 삼현, 휴림로봇, 티로보틱스
E10: =H10 -> 반도체 장비 | H10: 반도체 장비 | I10: semi_equipment | J10: 한미반도체, 리노공업, 이오테크닉스, 원익홀딩스, 고영, 주성엔지니어링
C11: =G11 | E11: =H11 -> 반도체 재료/부품 | H11: 반도체 재료/부품 | I11: semi_component | J11: ISC, 동진쎄미켐, 티씨케이, 하나마이크론, 에스앤에스텍
E12: =H12 -> 엔터테인먼트 | H12: 엔터테인먼트 | I12: entertainment | J12: 하이브, JYP Ent, 에스엠, 큐브엔터, 스튜디오드래곤, 디어유
E13: =H13 -> 여행 | H13: 여행 | I13: travel | J13: 롯데관광개발, 하나투어, 노랑풍선, 참좋은여행, 그래디언트
E14: =H14 -> 조선 | H14: 조선 | I14: ship_industry | J14: HD현대중공업, 한화오션, 대한조선, HJ중공업, 동일스틸럭스
E15: =H15 -> 조선기자재 | H15: 조선기자재 | I15: ship_equip | J15: 세진중공업, 현대힘스, 화인베스틸, 오리엔탈정공, 태웅
C16: =F16 -> 소재/부품/장비 | E16: =H16 | F16: 소재/부품/장비 | G16: Materials, Device
E17: =H17 -> OLED(유기발광다이오드) | H17: OLED(유기발광다이오드) | I17: oled | J17: 원익IPS, 한솔케미칼, 필옵틱스, 덕산네오룩스, 나노신소재, PI첨단소재
E18: =H18 -> 갤럭시부품주 | H18: 갤럭시부품주 | I18: gallexy | J18: 덕산네오룩스, 코리아써키트, 시노펙스, 켐트로닉스, 이녹스첨단소재, 나무가
E19: =H19 -> 아이폰 | H19: 아이폰 | I19: iphone | J19: 자화전자, 덕산네오룩스, LG디스플레이, 에스켐, 비에이치
C20: =F20 -> 바이오 | E20: =H20 | F20: 바이오 | G20: Bio
E21: =H21 -> 건강기능식품 | H21: 건강기능식품 | I21: healthfood | J21: KT&G, HK이노엔, 메디포스트, HLB제약, 휴온스
E22: =H22 -> 마이크로바이옴 | H22: 마이크로바이옴 | I22: microbiome | J22: 고바이오랩, 지놈앤컴퍼니, 랩지노믹스, 마크로젠, HLB제넥스 | K22: 미생물군집 게놈의 합성어, 신약개발 및 불치병 치료
E23: =H23 -> 바이오시밀러 | H23: 바이오시밀러 | I23: biosimilar | J23: 셀트리온, 팬젠, 한올바이오파마, 알테오젠, 경동제약, 종근당
E24: =H24 -> 비만치료제 | H24: 비만치료제 | I24: obesity | J24: 인벤티지랩, 펩트론, 일동홀딩스, 일동제약, 동운아나텍, 동아에스티, 큐라티스, 라파스
C25: =F25 -> 질병 | F25: 질병 | G25: Disease
C26: =F26 | E26: =H26 -> 구제역/광우병 | H26: 구제역/광우병 | I26: disease_food | J26: 동원사업, 하림, 이지홀딩스, 팜스토리, 한일사료, 정다운 | K26: 소고기 대체상품 수혜
E27: =H27 -> 구충제 | H27: 구충제 | I27: disease_anthelmintics | J27: 알리코제약, 진바이오텍, 체시스, 조아제약, 대성미생물
E28: =H28 -> 엠폭스(원숭이두창) | H28: 엠폭스(원숭이두창) | I28: disease_mpox | J28: 케스피온, 파미셀, 미코바이오메드, 바이오노트, 녹십자엠에스, 세니젠
E29: =H29 -> 치매 | H29: 치매 | I29: dementia | J29: 듀켐바이오, 지투지바이오, 보로노이, 바이오스마트, 퓨처켐, 젬백스
E30: =H30 -> 탈모 | H30: 탈모 | I30: hairloss | J30: 제이투케이바이오, 명문제약, 샤페론, JW신약, 강스템바이오텍
C31: =F31 -> 신기술 | E31: =H31 | F31: 신기술 | G31: New Technology
E32: =H32 -> 2차전지 | H32: 2차전지 | I32: battery | J32: 에코프로, 에코프로비엠, 천보, 한농화성, 후성, 원익IPS
E33: =H33 -> AI 챗봇 | H33: AI 챗봇 | I33: ai_chatbot | J33: 이수페타시스, 아크릴, 솔트룩스, 셀바스AI, 폴라리스AI, 마음AI
E34: =H34 -> 온디바이스 AI | H34: 온디바이스 AI | I34: ai_ondevice | J34: 리노공업, 대덕전자, 심텍, 태성, 칩스앤미디어, 텔레칩스, 어보브반도체
E35: =H35 -> 의료 AI | H35: 의료 AI | I35: ai_medical | J35: 셀바스헬스케어, 뷰노, 딥노이드, 루닛, 라이프시맨틱스
E36: =H36 -> NFT(대체불가토큰) | H36: NFT(대체불가토큰) | I36: nft | J36: 다날, 갤럭시아머니트리, 폴라리스오피스, 아폰, 서울옥션
E37: =H37 -> 증강현실(AR) | H37: 증강현실(AR) | I37: ar | J37: 라온텍, 에스피지, 덱스터, 포니링크, 링크웨어
E38: =H38 -> 가상현실(VR) | H38: 가상현실(VR) | I38: vr | J38: 나무가, SOOP, 하이비젼시스템, 스코넥, 위지웍스튜디오
E39: =H39 -> 가상화폐(비트코인 등) | H39: 가상화폐(비트코인 등) | I39: coin | J39: 우리기술투자, 다날, KG모빌리언스, 비트플랫닛, 위지트, 비트맥스
E40: =H40 -> 드론 | H40: 드론 | I40: drone | J40: 네온테크, 베셀, 에이럭스, 휴니드, 제이씨현시스템
E41: =H41 -> 딥페이크 | H41: 딥페이크 | I41: deepfake | J41: 아이씨디케이, 이스트소프트, 샌즈랩, 라온시큐어, 알체라, M83
...

Sheet Sheet1
A1: ■ 테마 색/클래스 매핑
B3: themeClass
D5: =인포스탁!I5 -> 0
D6: =인포스탁!I6 -> construct_industry | E6: t- | F6: =D6 -> construct_industry | G6: =인포스탁!H6 -> 건설중소형
D7: =인포스탁!I7 -> construct_equip | E7: t- | F7: =D7 -> construct_equip | G7: =인포스탁!H7 -> 건설기계
D8: =인포스탁!I8 -> game | E8: t- | F8: =D8 -> game | G8: =인포스탁!H8 -> 게임
D9: =인포스탁!I9 -> robot | E9: t- | F9: =D9 -> robot | G9: =인포스탁!H9 -> 로봇
D10: =인포스탁!I10 -> semi_equipment | E10: t- | F10: =D10 -> semi_equipment | G10: =인포스탁!H10 -> 반도체 장비
D11: =인포스탁!I11 -> semi_component | E11: t- | F11: =D11 -> semi_component | G11: =인포스탁!H11 -> 반도체 재료/부품
D12: =인포스탁!I12 -> entertainment | E12: t- | F12: =D12 -> entertainment | G12: =인포스탁!H12 -> 엔터테인먼트
D13: =인포스탁!I13 -> travel | E13: t- | F13: =D13 -> travel | G13: =인포스탁!H13 -> 여행
D14: =인포스탁!I14 -> ship_industry | E14: t- | F14: =D14 -> ship_industry | G14: =인포스탁!H14 -> 조선
D15: =인포스탁!I15 -> ship_equip | E15: t- | F15: =D15 -> ship_equip | G15: =인포스탁!H15 -> 조선기자재
D16: =인포스탁!I16 | E16: t- | F16: =D16 | G16: =인포스탁!H16
D17: =인포스탁!I17 -> oled | E17: t- | F17: =D17 -> oled | G17: =인포스탁!H17 -> OLED(유기발광다이오드)
... D77: =인포스탁!I77 -> rivian | E77: t- | F77: =D77 -> rivian | G77: =인포스탁!H77 -> 리비안

Sheet Sheet2
C2: 코드 | E2: 종목명 | G2: 테마 | I2: 설명 | K2: 테그
C3: ticker | E3: name | G3: theme | I3: desc | K3: tags
B4: ticker | C4: [035420] | D4: name | E4: NAVER | F4: theme | G4: ai | H4: desc | I4: 검색/클라우드 기반 AI 서비스 확대 | J4: tags | K4: ["AI","클라우드","플랫폼"]
B5: ticker | C5: [005930] | D5: name | E5: 삼성전자 | F5: theme | G5: semi | H5: desc | I5: 메모리/파운드리 양대축 | J5: tags | K5: ["반도체","메모리","파운드리"]
B6: ticker | C6: [373220] | D6: name | E6: LG에너지솔루션 | F6: theme | G6: battery | H6: desc | I6: EV용 배터리 생산 글로벌 확대 | J6: tags | K6: ["배터리","EV","원통형"]
B7: ticker | C7: [068270] | D7: name | E7: 셀트리온 | F7: theme | G7: bio | H7: desc | I7: 바이오시밀러와 신약 개발 | J7: tags | K7: ["바이오","시밀러","항체"]
B8: ticker | C8: [000660] | D8: name | E8: SK하이닉스 | F8: theme | G8: semi | H8: desc | I8: HBM 수요 증가로 메모리 강세 | J8: tags | K8: ["반도체","HBM","메모리"]
B9: ticker | C9: [086520] | D9: name | E9: 에코프로 | F9: theme | G9: battery | H9: desc | I9: 양극재 중심의 2차전지 소재 | J9: tags | K9: ["배터리","소재","양극재"]
B10: ticker | C10: [302440] | D10: name | E10: SK바이오사이언스 | F10: theme | G10: bio | H10: desc | I10: 백신 플랫폼 및 CMO | J10: tags | K10: ["바이오","백신","CMO"]
B11: ticker | C11: [096770] | D11: name | E11: SK이노베이션 | F11: theme | G11: green | H11: desc | I11: 친환경 에너지 전환과 소재 | J11: tags | K11: ["친환경","에너지","배터리"]
B12: ticker | C12: [034730] | D12: name | E12: SK | F12: theme | G12: ai | H12: desc | I12: AI·데이터센터 투자 확대 | J12: tags | K12: ["AI","데이터센터","지주"]
B13: ticker | C13: [247540] | D13: name | E13: 에코프로비엠 | F13: theme | G13: battery | H13: desc | I13: 고니켈 양극재 주력 | J13: tags | K13: ["배터리","양극재","소재"]
B14: ticker | C14: [066570] | D14: name | E14: LG전자 | F14: theme | G14: ai | H14: desc | I14: 가전·전장에 AI 융합 | J14: tags | K14: ["AI","가전","전장"]
B15: ticker | C15: [005380] | D15: name | E15: 현대차 | F15: theme | G15: green | H15: desc | I15: EV 라인업 확장 및 수소 | J15: tags | K15: ["친환경","EV","수소"]
... B314: ticker | C314: [354320] | D314: name | E314: 알멕 | F314: theme | G314: rivian | H314: desc | I314: 전기차 플랫폼 부품과 이차전지 부품을 생산하며, 알루미늄 주조부터 조립, 표면처리까지 일관생산체계를 구축, 폭스바겐, 아우디, 제너럴모터스 등 글로벌 업체에 공급하고 있음. | J314: tags | K314: ["2차전지 배터리 부품계약","알루미늄 압출 전문업체"]
B315: ticker | C315: [] | D315: name | F315: theme | H315: desc | J315: tags | K315: [""]
B316: ticker | C316: [] | D316: name | F316: theme | H316: desc | J316: tags | K316: [""]
B317: ticker | C317: [] | D317: name | F317: theme | H317: desc | J317: tags | K317: [""]

Sheet 신기술
A1: ■ 인포스탁 테마종목
B2: 섹터 | C2: 인포스탁 | D2: 코드 | E2: 종목명 | F2: 테마 | G2: 설명 | H2: 테그
B3: sector | C3: infostock | D3: ticker | E3: name | F3: theme | G3: desc | H3: tags
D4: [035420] | E4: NAVER | F4: ai | G4: 검색/클라우드 기반 AI 서비스 확대 | H4: ["AI","클라우드","플랫폼"]
D5: [005930] | E5: 삼성전자 | F5: semi | G5: 메모리/파운드리 양대축 | H5: ["반도체","메모리","파운드리"]
D6: [373220] | E6: LG에너지솔루션 | F6: battery | G6: EV용 배터리 생산 글로벌 확대 | H6: ["배터리","EV","원통형"]
D7: [068270] | E7: 셀트리온 | F7: bio | G7: 바이오시밀러와 신약 개발 | H7: ["바이오","시밀러","항체"]
D8: [000660] | E8: SK하이닉스 | F8: semi | G8: HBM 수요 증가로 메모리 강세 | H8: ["반도체","HBM","메모리"]
D9: [086520] | E9: 에코프로 | F9: battery | G9: 양극재 중심의 2차전지 소재 | H9: ["배터리","소재","양극재"]
D10: [302440] | E10: SK바이오사이언스 | F10: bio | G10: 백신 플랫폼 및 CMO | H10: ["바이오","백신","CMO"]
D11: [096770] | E11: SK이노베이션 | F11: green | G11: 친환경 에너지 전환과 소재 | H11: ["친환경","에너지","배터리"]
D12: [034730] | E12: SK | F12: ai | G12: AI·데이터센터 투자 확대 | H12: ["AI","데이터센터","지주"]
D13: [247540] | E13: 에코프로비엠 | F13: battery | G13: 고니켈 양극재 주력 | H13: ["배터리","양극재","소재"]
D14: [066570] | E14: LG전자 | F14: ai | G14: 가전·전장에 AI 융합 | H14: ["AI","가전","전장"]
D15: [005380] | E15: 현대차 | F15: green | G15: EV 라인업 확장 및 수소 | H15: ["친환경","EV","수소"]
C18: 2차전지 | D18: [373220] | E18: LG에너지솔루션 | F18: battery | G18: EV, ESS, IT기기 등에 적용되는 전지, LG화학에서 분리 | H18: ["2차전지","LFP","리튜인산철","나트륨이온"]
C19: 2차전지 | D19: [096770] | E19: SK이노베이션 | F19: battery | G19: 석유·화학, LNG, 전력, 배터리 등이 포함된 포트폴리오를 구축 | H19: ["2차전지","생산","전고체","LNG"]
C20: 2차전지 | D20: [006400] | E20: 삼성SDI | F20: battery | G20: 리튬이온 2차전지, 반도체 및 디스플레이 소재를 생산/판매 | H20: ["2차전지","생산","전고체","반도체"]
C22: 2차전지 | D22: [086520] | E22: 에코프로 | F22: battery | G22: 양극재 중심의 2차전지 소재 | H22: ["2차전지","소재","양극재"]
C23: 2차전지 | D23: [247540] | E23: 에코프로비엠 | F23: battery | G23: 소재사업부문 물적분할, 양극소개 제조 판매 | H23: ["2차전지","소재","양극재", "니켈"]
C24: 2차전지 | D24: [278280] | E24: 천보 | F24: battery | H24: ["2차전지","반도체","삼성전자", "SK하이닉스"]
C25: 2차전지 | D25: [011500] | E25: 한농화성 | F25: battery | H25: ["2차전지","반도체","나노기술"]
C26: 2차전지 | D26: [093370] | E26: 후성 | F26: battery | H26: ["2차전지","반도체","삼성전자", "SK하이닉스"]
C27: 2차전지 | D27: [240810] | E27: 원익IPS | F27: battery | H27: ["2차전지","3D NAND","DRAM","반도체","디스플레이"]

Sheet 테마종목
A1: ■ 인포스탁 테마종목
B2: 인포스탁 | C2: 코드 | D2: 종목명 | E2: 테마 | F2: 설명 | G2: 테그
B3: infostock | C3: ticker | D3: name | E3: theme | F3: desc | G3: tags
C4: [035420] | D4: NAVER | E4: ai | F4: 검색/클라우드 기반 AI 서비스 확대 | G4: ["AI","클라우드","플랫폼"]
B5: semi | C5: [005930] | D5: 삼성전자 | E5: semi | F5: 메모리/파운드리 양대축 | G5: ["반도체","메모리","파운드리"]
B6: battery | C6: [373220] | D6: LG에너지솔루션 | E6: battery | F6: EV용 배터리 생산 글로벌 확대 | G6: ["배터리","EV","원통형"]
B7: bio | C7: [068270] | D7: 셀트리온 | E7: bio | F7: 바이오시밀러와 신약 개발 | G7: ["바이오","시밀러","항체"]
B8: semi | C8: [000660] | D8: SK하이닉스 | E8: semi | F8: HBM 수요 증가로 메모리 강세 | G8: ["반도체","HBM","메모리"]
B9: battery | C9: [086520] | D9: 에코프로 | E9: battery | F9: 양극재 중심의 2차전지 소재 | G9: ["배터리","소재","양극재"]
B10: bio | C10: [302440] | D10: SK바이오사이언스 | E10: bio | F10: 백신 플랫폼 및 CMO | G10: ["바이오","백신","CMO"]
B11: green | C11: [096770] | D11: SK이노베이션 | E11: green | F11: 친환경 에너지 전환과 소재 | G11: ["친환경","에너지","배터리"]
B12: ai | C12: [034730] | D12: SK | E12: ai | F12: AI·데이터센터 투자 확대 | G12: ["AI","데이터센터","지주"]
B13: battery | C13: [247540] | D13: 에코프로비엠 | E13: battery | F13: 고니켈 양극재 주력 | G13: ["배터리","양극재","소재"]
B14: ai | C14: [066570] | D14: LG전자 | E14: ai | F14: 가전·전장에 AI 융합 | G14: ["AI","가전","전장"]
B15: green | C15: [005380] | D15: 현대차 | E15: green | F15: EV 라인업 확장 및 수소 | G15: ["친환경","EV","수소"]
